# Summary of Errors

- **Mouse Genome Database**
  `[mgi] failed to resolve: ('Connection aborted.', ConnectionResetError(104, 'Connection reset by peer'))`

## Mouse Genome Database

Using class: `MGIGetter`

```python-traceback
Traceback (most recent call last):
  File "/home/runner/work/bioversions/bioversions/.tox/update/lib/python3.12/site-packages/urllib3/connectionpool.py", line 787, in urlopen
    response = self._make_request(
               ^^^^^^^^^^^^^^^^^^^
  File "/home/runner/work/bioversions/bioversions/.tox/update/lib/python3.12/site-packages/urllib3/connectionpool.py", line 488, in _make_request
    raise new_e
  File "/home/runner/work/bioversions/bioversions/.tox/update/lib/python3.12/site-packages/urllib3/connectionpool.py", line 464, in _make_request
    self._validate_conn(conn)
  File "/home/runner/work/bioversions/bioversions/.tox/update/lib/python3.12/site-packages/urllib3/connectionpool.py", line 1093, in _validate_conn
    conn.connect()
  File "/home/runner/work/bioversions/bioversions/.tox/update/lib/python3.12/site-packages/urllib3/connection.py", line 790, in connect
    sock_and_verified = _ssl_wrap_socket_and_match_hostname(
                        ^^^^^^^^^^^^^^^^^^^^^^^^^^^^^^^^^^^^
  File "/home/runner/work/bioversions/bioversions/.tox/update/lib/python3.12/site-packages/urllib3/connection.py", line 969, in _ssl_wrap_socket_and_match_hostname
    ssl_sock = ssl_wrap_socket(
               ^^^^^^^^^^^^^^^^
  File "/home/runner/work/bioversions/bioversions/.tox/update/lib/python3.12/site-packages/urllib3/util/ssl_.py", line 480, in ssl_wrap_socket
    ssl_sock = _ssl_wrap_socket_impl(sock, context, tls_in_tls, server_hostname)
               ^^^^^^^^^^^^^^^^^^^^^^^^^^^^^^^^^^^^^^^^^^^^^^^^^^^^^^^^^^^^^^^^^
  File "/home/runner/work/bioversions/bioversions/.tox/update/lib/python3.12/site-packages/urllib3/util/ssl_.py", line 524, in _ssl_wrap_socket_impl
    return ssl_context.wrap_socket(sock, server_hostname=server_hostname)
           ^^^^^^^^^^^^^^^^^^^^^^^^^^^^^^^^^^^^^^^^^^^^^^^^^^^^^^^^^^^^^^
  File "/opt/hostedtoolcache/Python/3.12.11/x64/lib/python3.12/ssl.py", line 455, in wrap_socket
    return self.sslsocket_class._create(
           ^^^^^^^^^^^^^^^^^^^^^^^^^^^^^
  File "/opt/hostedtoolcache/Python/3.12.11/x64/lib/python3.12/ssl.py", line 1041, in _create
    self.do_handshake()
  File "/opt/hostedtoolcache/Python/3.12.11/x64/lib/python3.12/ssl.py", line 1319, in do_handshake
    self._sslobj.do_handshake()
ConnectionResetError: [Errno 104] Connection reset by peer

During handling of the above exception, another exception occurred:

Traceback (most recent call last):
  File "/home/runner/work/bioversions/bioversions/.tox/update/lib/python3.12/site-packages/requests/adapters.py", line 644, in send
    resp = conn.urlopen(
           ^^^^^^^^^^^^^
  File "/home/runner/work/bioversions/bioversions/.tox/update/lib/python3.12/site-packages/urllib3/connectionpool.py", line 841, in urlopen
    retries = retries.increment(
              ^^^^^^^^^^^^^^^^^^
  File "/home/runner/work/bioversions/bioversions/.tox/update/lib/python3.12/site-packages/urllib3/util/retry.py", line 474, in increment
    raise reraise(type(error), error, _stacktrace)
          ^^^^^^^^^^^^^^^^^^^^^^^^^^^^^^^^^^^^^^^^
  File "/home/runner/work/bioversions/bioversions/.tox/update/lib/python3.12/site-packages/urllib3/util/util.py", line 38, in reraise
    raise value.with_traceback(tb)
  File "/home/runner/work/bioversions/bioversions/.tox/update/lib/python3.12/site-packages/urllib3/connectionpool.py", line 787, in urlopen
    response = self._make_request(
               ^^^^^^^^^^^^^^^^^^^
  File "/home/runner/work/bioversions/bioversions/.tox/update/lib/python3.12/site-packages/urllib3/connectionpool.py", line 488, in _make_request
    raise new_e
  File "/home/runner/work/bioversions/bioversions/.tox/update/lib/python3.12/site-packages/urllib3/connectionpool.py", line 464, in _make_request
    self._validate_conn(conn)
  File "/home/runner/work/bioversions/bioversions/.tox/update/lib/python3.12/site-packages/urllib3/connectionpool.py", line 1093, in _validate_conn
    conn.connect()
  File "/home/runner/work/bioversions/bioversions/.tox/update/lib/python3.12/site-packages/urllib3/connection.py", line 790, in connect
    sock_and_verified = _ssl_wrap_socket_and_match_hostname(
                        ^^^^^^^^^^^^^^^^^^^^^^^^^^^^^^^^^^^^
  File "/home/runner/work/bioversions/bioversions/.tox/update/lib/python3.12/site-packages/urllib3/connection.py", line 969, in _ssl_wrap_socket_and_match_hostname
    ssl_sock = ssl_wrap_socket(
               ^^^^^^^^^^^^^^^^
  File "/home/runner/work/bioversions/bioversions/.tox/update/lib/python3.12/site-packages/urllib3/util/ssl_.py", line 480, in ssl_wrap_socket
    ssl_sock = _ssl_wrap_socket_impl(sock, context, tls_in_tls, server_hostname)
               ^^^^^^^^^^^^^^^^^^^^^^^^^^^^^^^^^^^^^^^^^^^^^^^^^^^^^^^^^^^^^^^^^
  File "/home/runner/work/bioversions/bioversions/.tox/update/lib/python3.12/site-packages/urllib3/util/ssl_.py", line 524, in _ssl_wrap_socket_impl
    return ssl_context.wrap_socket(sock, server_hostname=server_hostname)
           ^^^^^^^^^^^^^^^^^^^^^^^^^^^^^^^^^^^^^^^^^^^^^^^^^^^^^^^^^^^^^^
  File "/opt/hostedtoolcache/Python/3.12.11/x64/lib/python3.12/ssl.py", line 455, in wrap_socket
    return self.sslsocket_class._create(
           ^^^^^^^^^^^^^^^^^^^^^^^^^^^^^
  File "/opt/hostedtoolcache/Python/3.12.11/x64/lib/python3.12/ssl.py", line 1041, in _create
    self.do_handshake()
  File "/opt/hostedtoolcache/Python/3.12.11/x64/lib/python3.12/ssl.py", line 1319, in do_handshake
    self._sslobj.do_handshake()
urllib3.exceptions.ProtocolError: ('Connection aborted.', ConnectionResetError(104, 'Connection reset by peer'))

During handling of the above exception, another exception occurred:

Traceback (most recent call last):
  File "/home/runner/work/bioversions/bioversions/src/bioversions/sources/__init__.py", line 265, in iter_versions
    yv = resolve(cls)
         ^^^^^^^^^^^^
  File "/home/runner/work/bioversions/bioversions/src/bioversions/sources/__init__.py", line 187, in resolve
    return _resolve_helper_cached(name)
           ^^^^^^^^^^^^^^^^^^^^^^^^^^^^
  File "/home/runner/work/bioversions/bioversions/.tox/update/lib/python3.12/site-packages/cachier/core.py", line 393, in func_wrapper
    return _call(*args, **kwargs)
           ^^^^^^^^^^^^^^^^^^^^^^
  File "/home/runner/work/bioversions/bioversions/.tox/update/lib/python3.12/site-packages/cachier/core.py", line 332, in _call
    return _calc_entry(core, key, func, args, kwds)
           ^^^^^^^^^^^^^^^^^^^^^^^^^^^^^^^^^^^^^^^^
  File "/home/runner/work/bioversions/bioversions/.tox/update/lib/python3.12/site-packages/cachier/core.py", line 66, in _calc_entry
    func_res = func(*args, **kwds)
               ^^^^^^^^^^^^^^^^^^^
  File "/home/runner/work/bioversions/bioversions/src/bioversions/sources/__init__.py", line 197, in _resolve_helper_cached
    return getter.resolve()
           ^^^^^^^^^^^^^^^^
  File "/home/runner/work/bioversions/bioversions/src/bioversions/utils.py", line 213, in resolve
    version=cls.version,
            ^^^^^^^^^^^
  File "/home/runner/work/bioversions/bioversions/src/bioversions/utils.py", line 91, in version
    if isinstance(cls._cache_prop, str):
                  ^^^^^^^^^^^^^^^
  File "/home/runner/work/bioversions/bioversions/src/bioversions/utils.py", line 85, in _cache_prop
    cls._cache = cls().get()
                 ^^^^^^^^^^^
  File "/home/runner/work/bioversions/bioversions/src/bioversions/sources/mgi.py", line 22, in get
    soup = get_soup(HOMEPAGE)
           ^^^^^^^^^^^^^^^^^^
  File "/home/runner/work/bioversions/bioversions/.tox/update/lib/python3.12/site-packages/pystow/utils.py", line 1441, in get_soup
    res = requests.get(url, verify=verify, timeout=timeout or 15, headers=headers)
          ^^^^^^^^^^^^^^^^^^^^^^^^^^^^^^^^^^^^^^^^^^^^^^^^^^^^^^^^^^^^^^^^^^^^^^^^
  File "/home/runner/work/bioversions/bioversions/.tox/update/lib/python3.12/site-packages/requests/api.py", line 73, in get
    return request("get", url, params=params, **kwargs)
           ^^^^^^^^^^^^^^^^^^^^^^^^^^^^^^^^^^^^^^^^^^^^
  File "/home/runner/work/bioversions/bioversions/.tox/update/lib/python3.12/site-packages/requests/api.py", line 59, in request
    return session.request(method=method, url=url, **kwargs)
           ^^^^^^^^^^^^^^^^^^^^^^^^^^^^^^^^^^^^^^^^^^^^^^^^^
  File "/home/runner/work/bioversions/bioversions/.tox/update/lib/python3.12/site-packages/requests/sessions.py", line 589, in request
    resp = self.send(prep, **send_kwargs)
           ^^^^^^^^^^^^^^^^^^^^^^^^^^^^^^
  File "/home/runner/work/bioversions/bioversions/.tox/update/lib/python3.12/site-packages/requests/sessions.py", line 703, in send
    r = adapter.send(request, **kwargs)
        ^^^^^^^^^^^^^^^^^^^^^^^^^^^^^^^
  File "/home/runner/work/bioversions/bioversions/.tox/update/lib/python3.12/site-packages/requests/adapters.py", line 659, in send
    raise ConnectionError(err, request=request)
requests.exceptions.ConnectionError: ('Connection aborted.', ConnectionResetError(104, 'Connection reset by peer'))

```
