# Summary of Errors

- **BiGG** `[BiGG] failed to resolve`

## BiGG

Using class: `BiGGGetter`

```python-traceback
Traceback (most recent call last):
  File "/home/runner/work/bioversions/bioversions/.tox/update/lib/python3.12/site-packages/urllib3/connection.py", line 198, in _new_conn
    sock = connection.create_connection(
           ^^^^^^^^^^^^^^^^^^^^^^^^^^^^^
  File "/home/runner/work/bioversions/bioversions/.tox/update/lib/python3.12/site-packages/urllib3/util/connection.py", line 85, in create_connection
    raise err
  File "/home/runner/work/bioversions/bioversions/.tox/update/lib/python3.12/site-packages/urllib3/util/connection.py", line 73, in create_connection
    sock.connect(sa)
TimeoutError: timed out

The above exception was the direct cause of the following exception:

Traceback (most recent call last):
  File "/home/runner/work/bioversions/bioversions/.tox/update/lib/python3.12/site-packages/urllib3/connectionpool.py", line 787, in urlopen
    response = self._make_request(
               ^^^^^^^^^^^^^^^^^^^
  File "/home/runner/work/bioversions/bioversions/.tox/update/lib/python3.12/site-packages/urllib3/connectionpool.py", line 493, in _make_request
    conn.request(
  File "/home/runner/work/bioversions/bioversions/.tox/update/lib/python3.12/site-packages/urllib3/connection.py", line 445, in request
    self.endheaders()
  File "/opt/hostedtoolcache/Python/3.12.10/x64/lib/python3.12/http/client.py", line 1333, in endheaders
    self._send_output(message_body, encode_chunked=encode_chunked)
  File "/opt/hostedtoolcache/Python/3.12.10/x64/lib/python3.12/http/client.py", line 1093, in _send_output
    self.send(msg)
  File "/opt/hostedtoolcache/Python/3.12.10/x64/lib/python3.12/http/client.py", line 1037, in send
    self.connect()
  File "/home/runner/work/bioversions/bioversions/.tox/update/lib/python3.12/site-packages/urllib3/connection.py", line 276, in connect
    self.sock = self._new_conn()
                ^^^^^^^^^^^^^^^^
  File "/home/runner/work/bioversions/bioversions/.tox/update/lib/python3.12/site-packages/urllib3/connection.py", line 207, in _new_conn
    raise ConnectTimeoutError(
urllib3.exceptions.ConnectTimeoutError: (<urllib3.connection.HTTPConnection object at 0x7f1d32d21df0>, 'Connection to bigg.ucsd.edu timed out. (connect timeout=15)')

The above exception was the direct cause of the following exception:

Traceback (most recent call last):
  File "/home/runner/work/bioversions/bioversions/.tox/update/lib/python3.12/site-packages/requests/adapters.py", line 667, in send
    resp = conn.urlopen(
           ^^^^^^^^^^^^^
  File "/home/runner/work/bioversions/bioversions/.tox/update/lib/python3.12/site-packages/urllib3/connectionpool.py", line 841, in urlopen
    retries = retries.increment(
              ^^^^^^^^^^^^^^^^^^
  File "/home/runner/work/bioversions/bioversions/.tox/update/lib/python3.12/site-packages/urllib3/util/retry.py", line 519, in increment
    raise MaxRetryError(_pool, url, reason) from reason  # type: ignore[arg-type]
    ^^^^^^^^^^^^^^^^^^^^^^^^^^^^^^^^^^^^^^^^^^^^^^^^^^^
urllib3.exceptions.MaxRetryError: HTTPConnectionPool(host='bigg.ucsd.edu', port=80): Max retries exceeded with url: /api/v2/database_version (Caused by ConnectTimeoutError(<urllib3.connection.HTTPConnection object at 0x7f1d32d21df0>, 'Connection to bigg.ucsd.edu timed out. (connect timeout=15)'))

During handling of the above exception, another exception occurred:

Traceback (most recent call last):
  File "/home/runner/work/bioversions/bioversions/src/bioversions/sources/__init__.py", line 257, in iter_versions
    yv = resolve(cls.name)
         ^^^^^^^^^^^^^^^^^
  File "/home/runner/work/bioversions/bioversions/src/bioversions/sources/__init__.py", line 178, in resolve
    return _resolve_helper_cached(name)
           ^^^^^^^^^^^^^^^^^^^^^^^^^^^^
  File "/home/runner/work/bioversions/bioversions/.tox/update/lib/python3.12/site-packages/cachier/core.py", line 258, in func_wrapper
    return _calc_entry(core, key, func, args, kwds)
           ^^^^^^^^^^^^^^^^^^^^^^^^^^^^^^^^^^^^^^^^
  File "/home/runner/work/bioversions/bioversions/.tox/update/lib/python3.12/site-packages/cachier/core.py", line 61, in _calc_entry
    func_res = func(*args, **kwds)
               ^^^^^^^^^^^^^^^^^^^
  File "/home/runner/work/bioversions/bioversions/src/bioversions/sources/__init__.py", line 185, in _resolve_helper_cached
    return _resolve_helper(name)
           ^^^^^^^^^^^^^^^^^^^^^
  File "/home/runner/work/bioversions/bioversions/src/bioversions/sources/__init__.py", line 196, in _resolve_helper
    return getter.resolve()
           ^^^^^^^^^^^^^^^^
  File "/home/runner/work/bioversions/bioversions/src/bioversions/utils.py", line 224, in resolve
    version=cls.version,
            ^^^^^^^^^^^
  File "/home/runner/work/bioversions/bioversions/src/bioversions/utils.py", line 102, in version
    if isinstance(cls._cache_prop, str):
                  ^^^^^^^^^^^^^^^
  File "/home/runner/work/bioversions/bioversions/src/bioversions/utils.py", line 96, in _cache_prop
    cls._cache = cls().get()
                 ^^^^^^^^^^^
  File "/home/runner/work/bioversions/bioversions/src/bioversions/sources/bigg.py", line 24, in get
    res = requests.get(URL, timeout=15).json()
          ^^^^^^^^^^^^^^^^^^^^^^^^^^^^^
  File "/home/runner/work/bioversions/bioversions/.tox/update/lib/python3.12/site-packages/requests/api.py", line 73, in get
    return request("get", url, params=params, **kwargs)
           ^^^^^^^^^^^^^^^^^^^^^^^^^^^^^^^^^^^^^^^^^^^^
  File "/home/runner/work/bioversions/bioversions/.tox/update/lib/python3.12/site-packages/requests/api.py", line 59, in request
    return session.request(method=method, url=url, **kwargs)
           ^^^^^^^^^^^^^^^^^^^^^^^^^^^^^^^^^^^^^^^^^^^^^^^^^
  File "/home/runner/work/bioversions/bioversions/.tox/update/lib/python3.12/site-packages/requests/sessions.py", line 589, in request
    resp = self.send(prep, **send_kwargs)
           ^^^^^^^^^^^^^^^^^^^^^^^^^^^^^^
  File "/home/runner/work/bioversions/bioversions/.tox/update/lib/python3.12/site-packages/requests/sessions.py", line 703, in send
    r = adapter.send(request, **kwargs)
        ^^^^^^^^^^^^^^^^^^^^^^^^^^^^^^^
  File "/home/runner/work/bioversions/bioversions/.tox/update/lib/python3.12/site-packages/requests/adapters.py", line 688, in send
    raise ConnectTimeout(e, request=request)
requests.exceptions.ConnectTimeout: HTTPConnectionPool(host='bigg.ucsd.edu', port=80): Max retries exceeded with url: /api/v2/database_version (Caused by ConnectTimeoutError(<urllib3.connection.HTTPConnection object at 0x7f1d32d21df0>, 'Connection to bigg.ucsd.edu timed out. (connect timeout=15)'))

```
